Workbook

Sheet DAHBOARD
B64: KEY INSIGHTS
B66: * Revenue declined 33% from its FY'12 peak ($48.0B) to FY'18 ($31.9B), while gross margin stayed remarkably stable at 60–64% the entire decade.
B67: * FY'17 net income collapsed to $1.28B (net margin just 4%) due to a one-time U.S. tax reform charge — not a business problem — and rebounded sharply to $6.5B in FY'18.
B68: * Free Cash Flow stayed healthy ($5.2B–$8.2B every year) even during the FY'17 net income crash, showing the underlying cash-generating business stayed strong.
B69: * Debt-to-Equity rose steadily from 0.47x (FY'09) to 2.29x (FY'18), while the Current Ratio stayed flat around 1.0x–1.3x — the company took on significantly more leverage without straining short-term liquidity.
B70: * ROE consistently outpaced ROA across all 10 years, confirming leverage was actively boosting shareholder returns.

Sheet KPI
B3: REVENUE (FY'18) | C3: Net Income | D3: GROSS MARGIN % | E3: ROE % | F3: FREE CASH FLOW
B4: ='P&L Clean'!K3 -> 31856 | C4: ='P&L Clean'!K15 -> 6476 | D4: =Ratios!K2 -> 0.63052486 | E4: =Ratios!K13 -> 0.33980481 | F4: =Ratios!K15 -> 5973
B5: =('P&L Clean'!K3-'P&L Clean'!J3)/'P&L Clean'!J3 -> -0.10036713 | C5: =('P&L Clean'!K15-'P&L Clean'!J15)/'P&L Clean'!J15 -> 4.0475448 | F5: =(Ratios!K15-Ratios!J15)/Ratios!J15 -> 0.13663178

Sheet P&L Clean
A1: Line Item
A2: in million USD | B2: FY '09 | C2: FY '10 | D2: FY '11 | E2: FY '12 | F2: FY '13 | G2: FY '14 | H2: FY '15 | I2: FY '16 | J2: FY '17 | K2: FY '18
A3: NET OPERATING REVENUES | B3: 30990 | C3: 35119 | D3: 46542 | E3: 48017 | F3: 46854 | G3: 45998 | H3: 44294 | I3: 41863 | J3: 35410 | K3: 31856
A4: Cost of goods sold | B4: 11088 | C4: 12693 | D4: 18215 | E4: 19053 | F4: 18421 | G4: 17889 | H4: 17482 | I4: 16465 | J4: 13255 | K4: 11770
A5: GROSS PROFIT | B5: 19902 | C5: 22426 | D5: 28327 | E5: 28964 | F5: 28433 | G5: 28109 | H5: 26812 | I5: 25398 | J5: 22155 | K5: 20086
A6: Selling, general and administrative expenses | B6: 11358 | C6: 13194 | D6: 17422 | E6: 17738 | F6: 17310 | G6: 17218 | H6: 16427 | I6: 15262 | J6: 12654 | K6: 10307
A7: Other operating charges | B7: 313 | C7: 819 | D7: 732 | E7: 447 | F7: 895 | G7: 1183 | H7: 1657 | I7: 1510 | J7: 1902 | K7: 1079
A8: OPERATING INCOME | B8: 8231 | C8: 8413 | D8: 10173 | E8: 10779 | F8: 10228 | G8: 9708 | H8: 8728 | I8: 8626 | J8: 7599 | K8: 8700
A9: Interest income | B9: 249 | C9: 317 | D9: 483 | E9: 471 | F9: 534 | G9: 594 | H9: 613 | I9: 642 | J9: 677 | K9: 682
A10: Interest expense | B10: 355 | C10: 733 | D10: 417 | E10: 397 | F10: 463 | G10: 483 | H10: 856 | I10: 733 | J10: 841 | K10: 919
A11: Equity income (loss) - net | B11: 781 | C11: 1025 | D11: 690 | E11: 819 | F11: 602 | G11: 769 | H11: 489 | I11: 835 | J11: 1071 | K11: 1008
A12: Other income (loss) - net | B12: 40 | C12: 5185 | D12: 529 | E12: 137 | F12: 576 | G12: -1263 | H12: 631 | I12: -1234 | J12: -1764 | K12: -1121
A13: INCOME BEFORE INCOME TAXES | B13: 8946 | C13: 14207 | D13: 11458 | E13: 11809 | F13: 11477 | G13: 9325 | H13: 9605 | I13: 8136 | J13: 6742 | K13: 8350
A14: Income taxes | B14: 2040 | C14: 2370 | D14: 2812 | E14: 2723 | F14: 2851 | G14: 2201 | H14: 2239 | I14: 1586 | J14: 5560 | K14: 1623
... A19: NET INCOME ATTRIBUTABLE TO SHAREOWNERS OF THE COCA-COLA COMPANY | B19: 6824 | C19: 11787 | D19: 8584 | E19: 9019 | F19: 8584 | G19: 7098 | H19: 7351 | I19: 6527 | J19: 1248 | K19: 6434

Sheet Balance Sheet Clean
A2: in million USD | B2: FY '09 | C2: FY '10 | D2: FY '11 | E2: FY '12 | F2: FY '13 | G2: FY '14 | H2: FY '15 | I2: FY '16 | J2: FY '17 | K2: FY '18
A3: Cash and cash equivalents | B3: 7021 | C3: 8517 | D3: 12803 | E3: 8442 | F3: 10414 | G3: 8958 | H3: 7309 | I3: 8555 | J3: 6006 | K3: 8926
A4: Short-term investments | B4: 2130 | C4: 2682 | D4: 1088 | E4: 5017 | F4: 6707 | G4: 9052 | H4: 8322 | I4: 9595 | J4: 9352 | K4: 2025
A5: Total cash, cash equivalents and short-term investments | B5: 9151 | C5: 11199 | D5: 13891 | E5: 13459 | F5: 17121 | G5: 18010 | H5: 15631 | I5: 18150 | J5: 15358 | K5: 10951
A6: Marketable securities | B6: 62 | C6: 138 | D6: 144 | E6: 3092 | F6: 3147 | G6: 3665 | H6: 4269 | I6: 4051 | J6: 5317 | K6: 5013
A7: Trade accounts receivable, less allowances | B7: 3758 | C7: 4430 | D7: 4920 | E7: 4759 | F7: 4873 | G7: 4466 | H7: 3941 | I7: 3856 | J7: 3667 | K7: 3396
A8: Inventories | B8: 2354 | C8: 2650 | D8: 3092 | E8: 3264 | F8: 3277 | G8: 3100 | H8: 2902 | I8: 2675 | J8: 2655 | K8: 2766
A9: Prepaid expenses and other assets | B9: 2226 | C9: 3162 | D9: 3450 | E9: 2781 | F9: 2886 | G9: 3066 | H9: 2752 | I9: 2481 | J9: 2000 | K9: 1962
A10: Assets held for sale | B10: 0 | C10: 0 | D10: 0 | E10: 2973 | F10: 0 | G10: 679 | H10: 3900 | I10: 0 | J10: 7329 | K10: 6546
A11: Assets held for sale | B11: 0 | C11: 0 | D11: 0 | E11: 0 | F11: 0 | G11: 0 | H11: 0 | I11: 2797 | J11: 219 | K11: 0
A12: Total current assets | B12: 17551 | C12: 21579 | D12: 25497 | E12: 30328 | F12: 31304 | G12: 32986 | H12: 33395 | I12: 34010 | J12: 36545 | K12: 30634
A13: Equity method investments | B13: 6217 | C13: 6954 | D13: 7233 | E13: 9216 | F13: 10393 | G13: 9947 | H13: 12318 | I13: 16260 | J13: 20856 | K13: 19407
A14: Other investments | B14: 538 | C14: 631 | D14: 1141 | E14: 1232 | F14: 1119 | G14: 3678 | H14: 3470 | I14: 989 | J14: 1096 | K14: 867
... A41: Total liabilities and equity | B41: 48671 | C41: 72921 | D41: 79974 | E41: 86174 | F41: 90055 | G41: 92023 | H41: 89996 | I41: 87270 | J41: 87896 | K41: 83216

Sheet Cash Flow Clean
A2: in million USD | B2: FY '09 | C2: FY '10 | D2: FY '11 | E2: FY '12 | F2: FY '13 | G2: FY '14 | H2: FY '15 | I2: FY '16 | J2: FY '17 | K2: FY '18
A3: Consolidated net income | B3: 6906 | C3: 11837 | D3: 8646 | E3: 9086 | F3: 8626 | G3: 7124 | H3: 7366 | I3: 6550 | J3: 1283 | K3: 6476
A4: Depreciation and amortization | B4: 1236 | C4: 1443 | D4: 1954 | E4: 1982 | F4: 1977 | G4: 1976 | H4: 1970 | I4: 1787 | J4: 1260 | K4: 1086
A5: (Income) Loss from discontinued operations | B5: 0 | C5: 0 | D5: 0 | E5: 0 | F5: 0 | G5: 0 | H5: 0 | I5: 0 | J5: -101 | K5: 251
A6: Net income from continuing operations | B6: 6909 | C6: 11837 | D6: 8646 | E6: 9086 | F6: 8626 | G6: 7124 | H6: 7366 | I6: 6550 | J6: 1182 | K6: 6727
A7: Stock-based compensation expense | B7: 241 | C7: 380 | D7: 354 | E7: 259 | F7: 227 | G7: 209 | H7: 236 | I7: 258 | J7: 219 | K7: 225
A8: Deferred income taxes | B8: 353 | C8: 604 | D8: 1035 | E8: 632 | F8: 648 | G8: -40 | H8: 73 | I8: -856 | J8: -1256 | K8: -450
A9: Equity (income) loss - net of dividends | B9: -359 | C9: -671 | D9: -269 | E9: -426 | F9: -201 | G9: -371 | H9: -122 | I9: -449 | J9: -628 | K9: -457
A10: Foreign currency adjustments | B10: 61 | C10: 151 | D10: 7 | E10: -130 | F10: 168 | G10: 415 | H10: -137 | I10: 158 | J10: 281 | K10: -38
A11: Significant (gains) losses on sales of assets - net | B11: -43 | C11: -645 | D11: -220 | E11: -98 | F11: -670 | G11: 831 | H11: -374 | I11: 1146 | J11: 1459 | K11: 189
A12: Other significant (gains) losses - net | B12: 0 | C12: -4713 | D12: 0 | E12: 0 | F12: 0 | G12: 0 | H12: 0 | I12: 0 | J12: 0 | K12: 0
A13: Other operating charges | B13: 134 | C13: 264 | D13: 214 | E13: 166 | F13: 465 | G13: 761 | H13: 929 | I13: 647 | J13: 1218 | K13: 558
A14: Other items | B14: 221 | C14: 512 | D14: -354 | E14: 254 | F14: 234 | G14: 149 | H14: 744 | I14: -224 | J14: -269 | K14: 682
... A38: Net increase (decrease) during the year | B38: 2320 | C38: 1496 | D38: 4286 | E38: -4361 | F38: 1972 | G38: -1456 | H38: -1649 | I38: 1246 | J38: -2477 | K38: 2945

Sheet Ratios
A1: Metric | B1: FY '09 | C1: FY '10 | D1: FY '11 | E1: FY '12 | F1: FY '13 | G1: FY '14 | H1: FY '15 | I1: FY '16 | J1: FY '17 | K1: FY '18
A2: Gross Margin % | B2: ='P&L Clean'!B5/'P&L Clean'!B3 -> 0.64220716 | C2: ='P&L Clean'!C5/'P&L Clean'!C3 -> 0.63857171 | D2: ='P&L Clean'!D5/'P&L Clean'!D3 -> 0.60863306 | E2: ='P&L Clean'!E5/'P&L Clean'!E3 -> 0.60320303 | F2: ='P&L Clean'!F5/'P&L Clean'!F3 -> 0.60684253 | G2: ='P&L Clean'!G5/'P&L Clean'!G3 -> 0.61109179 | H2: ='P&L Clean'!H5/'P&L Clean'!H3 -> 0.605319 | I2: ='P&L Clean'!I5/'P&L Clean'!I3 -> 0.60669326 | ... K2: ='P&L Clean'!K5/'P&L Clean'!K3 -> 0.63052486
A3: Operating Margin % | B3: ='P&L Clean'!B8/'P&L Clean'!B3 -> 0.26560181 | C3: ='P&L Clean'!C8/'P&L Clean'!C3 -> 0.23955693 | D3: ='P&L Clean'!D8/'P&L Clean'!D3 -> 0.21857677 | E3: ='P&L Clean'!E8/'P&L Clean'!E3 -> 0.224483 | F3: ='P&L Clean'!F8/'P&L Clean'!F3 -> 0.21829513 | G3: ='P&L Clean'!G8/'P&L Clean'!G3 -> 0.21105265 | H3: ='P&L Clean'!H8/'P&L Clean'!H3 -> 0.197047 | I3: ='P&L Clean'!I8/'P&L Clean'!I3 -> 0.20605308 | ... K3: ='P&L Clean'!K8/'P&L Clean'!K3 -> 0.27310397
A4: Net Profit Margin % | B4: ='P&L Clean'!B15/'P&L Clean'!B3 -> 0.22284608 | C4: ='P&L Clean'!C15/'P&L Clean'!C3 -> 0.33705402 | D4: ='P&L Clean'!D15/'P&L Clean'!D3 -> 0.18576769 | E4: ='P&L Clean'!E15/'P&L Clean'!E3 -> 0.18922465 | F4: ='P&L Clean'!F15/'P&L Clean'!F3 -> 0.18410381 | G4: ='P&L Clean'!G15/'P&L Clean'!G3 -> 0.1548763 | H4: ='P&L Clean'!H15/'P&L Clean'!H3 -> 0.16629792 | I4: ='P&L Clean'!I15/'P&L Clean'!I3 -> 0.15646275 | ... K4: ='P&L Clean'!K15/'P&L Clean'!K3 -> 0.2032898
A6: Revenue Growth % | C6: =('P&L Clean'!C3-'P&L Clean'!B3)/'P&L Clean'!B3 -> 0.13323653 | D6: =('P&L Clean'!D3-'P&L Clean'!C3)/'P&L Clean'!C3 -> 0.32526553 | E6: =('P&L Clean'!E3-'P&L Clean'!D3)/'P&L Clean'!D3 -> 0.031691805 | F6: =('P&L Clean'!F3-'P&L Clean'!E3)/'P&L Clean'!E3 -> -0.024220589 | G6: =('P&L Clean'!G3-'P&L Clean'!F3)/'P&L Clean'!F3 -> -0.018269518 | H6: =('P&L Clean'!H3-'P&L Clean'!G3)/'P&L Clean'!G3 -> -0.037045089 | I6: =('P&L Clean'!I3-'P&L Clean'!H3)/'P&L Clean'!H3 -> -0.05488328 | J6: =('P&L Clean'!J3-'P&L Clean'!I3)/'P&L Clean'!I3 -> -0.15414567 | K6: =('P&L Clean'!K3-'P&L Clean'!J3)/'P&L Clean'!J3 -> -0.10036713
A7: Net Income Growth % | C7: =('P&L Clean'!C15-'P&L Clean'!B15)/'P&L Clean'!B15 -> 0.7140168 | D7: =('P&L Clean'!D15-'P&L Clean'!C15)/'P&L Clean'!C15 -> -0.26957844 | E7: =('P&L Clean'!E15-'P&L Clean'!D15)/'P&L Clean'!D15 -> 0.050890585 | F7: =('P&L Clean'!F15-'P&L Clean'!E15)/'P&L Clean'!E15 -> -0.050627339 | G7: =('P&L Clean'!G15-'P&L Clean'!F15)/'P&L Clean'!F15 -> -0.17412474 | H7: =('P&L Clean'!H15-'P&L Clean'!G15)/'P&L Clean'!G15 -> 0.03396968 | I7: =('P&L Clean'!I15-'P&L Clean'!H15)/'P&L Clean'!H15 -> -0.11077926 | J7: =('P&L Clean'!J15-'P&L Clean'!I15)/'P&L Clean'!I15 -> -0.80412214 | K7: =('P&L Clean'!K15-'P&L Clean'!J15)/'P&L Clean'!J15 -> 4.0475448
A9: Current Ratio | B9: ='Balance Sheet Clean'!B12/'Balance Sheet Clean'!B29 -> 1.2791342 | C9: ='Balance Sheet Clean'!C12/'Balance Sheet Clean'!C29 -> 1.1659282 | D9: ='Balance Sheet Clean'!D12/'Balance Sheet Clean'!D29 -> 1.0499938 | E9: ='Balance Sheet Clean'!E12/'Balance Sheet Clean'!E29 -> 1.0901118 | F9: ='Balance Sheet Clean'!F12/'Balance Sheet Clean'!F29 -> 1.1255978 | G9: ='Balance Sheet Clean'!G12/'Balance Sheet Clean'!G29 -> 1.0189041 | H9: ='Balance Sheet Clean'!H12/'Balance Sheet Clean'!H29 -> 1.2401129 | I9: ='Balance Sheet Clean'!I12/'Balance Sheet Clean'!I29 -> 1.2818483 | ... K9: ='Balance Sheet Clean'!K12/'Balance Sheet Clean'!K29 -> 1.0482839
A10: Debt-to-Equity | B10: =('Balance Sheet Clean'!B30+'Balance Sheet Clean'!B24+'Balance Sheet Clean'!B25)/'Balance Sheet Clean'!B40 -> 0.46788448 | C10: =('Balance Sheet Clean'!C30+'Balance Sheet Clean'!C24+'Balance Sheet Clean'!C25)/'Balance Sheet Clean'!C40 -> 0.74774084 | D10: =('Balance Sheet Clean'!D30+'Balance Sheet Clean'!D24+'Balance Sheet Clean'!D25)/'Balance Sheet Clean'!D40 -> 0.89495943 | E10: =('Balance Sheet Clean'!E30+'Balance Sheet Clean'!E24+'Balance Sheet Clean'!E25)/'Balance Sheet Clean'!E40 -> 0.98317656 | F10: =('Balance Sheet Clean'!F30+'Balance Sheet Clean'!F24+'Balance Sheet Clean'!F25)/'Balance Sheet Clean'!F40 -> 1.1088218 | G10: =('Balance Sheet Clean'!G30+'Balance Sheet Clean'!G24+'Balance Sheet Clean'!G25)/'Balance Sheet Clean'!G40 -> 1.3659566 | H10: =('Balance Sheet Clean'!H30+'Balance Sheet Clean'!H24+'Balance Sheet Clean'!H25)/'Balance Sheet Clean'!H40 -> 1.7123118 | I10: =('Balance Sheet Clean'!I30+'Balance Sheet Clean'!I24+'Balance Sheet Clean'!I25)/'Balance Sheet Clean'!I40 -> 1.9685185 | ... K10: =('Balance Sheet Clean'!K30+'Balance Sheet Clean'!K24+'Balance Sheet Clean'!K25)/'Balance Sheet Clean'!K40 -> 2.285392
A12: ROA % | B12: ='P&L Clean'!B15/'Balance Sheet Clean'!B22 -> 0.14189148 | C12: ='P&L Clean'!C15/'Balance Sheet Clean'!C22 -> 0.16232635 | D12: ='P&L Clean'!D15/'Balance Sheet Clean'!D22 -> 0.10811014 | E12: ='P&L Clean'!E15/'Balance Sheet Clean'!E22 -> 0.10543784 | F12: ='P&L Clean'!F15/'Balance Sheet Clean'!F22 -> 0.095785909 | G12: ='P&L Clean'!G15/'Balance Sheet Clean'!G22 -> 0.077415429 | H12: ='P&L Clean'!H15/'Balance Sheet Clean'!H22 -> 0.081848082 | I12: ='P&L Clean'!I15/'Balance Sheet Clean'!I22 -> 0.075054429 | ... K12: ='P&L Clean'!K15/'Balance Sheet Clean'!K22 -> 0.077821573
A13: ROE % | B13: ='P&L Clean'!B15/'Balance Sheet Clean'!B40 -> 0.27246903 | C13: ='P&L Clean'!C15/'Balance Sheet Clean'!C40 -> 0.37797362 | D13: ='P&L Clean'!D15/'Balance Sheet Clean'!D40 -> 0.27085618 | E13: ='P&L Clean'!E15/'Balance Sheet Clean'!E40 -> 0.27393874 | F13: ='P&L Clean'!F15/'Balance Sheet Clean'!F40 -> 0.25795455 | G13: ='P&L Clean'!G15/'Balance Sheet Clean'!G40 -> 0.23310756 | H13: ='P&L Clean'!H15/'Balance Sheet Clean'!H40 -> 0.28590281 | I13: ='P&L Clean'!I15/'Balance Sheet Clean'!I40 -> 0.28208441 | ... K13: ='P&L Clean'!K15/'Balance Sheet Clean'!K40 -> 0.33980481
A15: Free Cash Flow | B15: ='Cash Flow Clean'!B16+'Cash Flow Clean'!B22 -> 6193 | C15: ='Cash Flow Clean'!C16+'Cash Flow Clean'!C22 -> 7317 | D15: ='Cash Flow Clean'!D16+'Cash Flow Clean'!D22 -> 6554 | E15: ='Cash Flow Clean'!E16+'Cash Flow Clean'!E22 -> 7865 | F15: ='Cash Flow Clean'!F16+'Cash Flow Clean'!F22 -> 7992 | G15: ='Cash Flow Clean'!G16+'Cash Flow Clean'!G22 -> 8209 | H15: ='Cash Flow Clean'!H16+'Cash Flow Clean'!H22 -> 7975 | I15: ='Cash Flow Clean'!I16+'Cash Flow Clean'!I22 -> 6534 | ... K15: ='Cash Flow Clean'!K16+'Cash Flow Clean'!K22 -> 5973
A16: FCF Margin % | B16: =Ratios!B15/'P&L Clean'!B3 -> 0.19983866 | C16: =Ratios!C15/'P&L Clean'!C3 -> 0.20834876 | D16: =Ratios!D15/'P&L Clean'!D3 -> 0.14081905 | E16: =Ratios!E15/'P&L Clean'!E3 -> 0.16379616 | F16: =Ratios!F15/'P&L Clean'!F3 -> 0.17057242 | G16: =Ratios!G15/'P&L Clean'!G3 -> 0.17846428 | H16: =Ratios!H15/'P&L Clean'!H3 -> 0.18004696 | I16: =Ratios!I15/'P&L Clean'!I3 -> 0.15608055 | ... K16: =Ratios!K15/'P&L Clean'!K3 -> 0.1875
A18: Total Liabilities | B18: ='Balance Sheet Clean'!B41-'Balance Sheet Clean'!B40 -> 23325 | C18: ='Balance Sheet Clean'!C41-'Balance Sheet Clean'!C40 -> 41604 | D18: ='Balance Sheet Clean'!D41-'Balance Sheet Clean'!D40 -> 48053 | E18: ='Balance Sheet Clean'!E41-'Balance Sheet Clean'!E40 -> 53006 | F18: ='Balance Sheet Clean'!F41-'Balance Sheet Clean'!F40 -> 56615 | G18: ='Balance Sheet Clean'!G41-'Balance Sheet Clean'!G40 -> 61462 | H18: ='Balance Sheet Clean'!H41-'Balance Sheet Clean'!H40 -> 64232 | I18: ='Balance Sheet Clean'!I41-'Balance Sheet Clean'!I40 -> 64050 | ... K18: ='Balance Sheet Clean'!K41-'Balance Sheet Clean'!K40 -> 64158
A19: Total Equity | B19: ='Balance Sheet Clean'!B40 -> 25346 | C19: ='Balance Sheet Clean'!C40 -> 31317 | D19: ='Balance Sheet Clean'!D40 -> 31921 | E19: ='Balance Sheet Clean'!E40 -> 33168 | F19: ='Balance Sheet Clean'!F40 -> 33440 | G19: ='Balance Sheet Clean'!G40 -> 30561 | H19: ='Balance Sheet Clean'!H40 -> 25764 | I19: ='Balance Sheet Clean'!I40 -> 23220 | ... K19: ='Balance Sheet Clean'!K40 -> 19058

Sheet COCA COLA CO
A1: Data provided by SimFin
A3: Profit & Loss statement
B4: in million USD | C4: FY '09 | D4: FY '10 | E4: FY '11 | F4: FY '12 | G4: FY '13 | H4: FY '14 | I4: FY '15 | J4: FY '16 | K4: FY '17 | L4: FY '18
B5: NET OPERATING REVENUES | C5: 30990 | D5: 35119 | E5: 46542 | F5: 48017 | G5: 46854 | H5: 45998 | I5: 44294 | J5: 41863 | K5: 35410 | L5: 31856
B6: Cost of goods sold | C6: 11088 | D6: 12693 | E6: 18215 | F6: 19053 | G6: 18421 | H6: 17889 | I6: 17482 | J6: 16465 | K6: 13255 | L6: 11770
B7: Gross Profit | C7: 19902 | D7: 22426 | E7: 28327 | F7: 28964 | G7: 28433 | H7: 28109 | I7: 26812 | J7: 25398 | K7: 22155 | L7: 20086
B8: Selling, general and administrative expenses | C8: 11358 | D8: 13194 | E8: 17422 | F8: 17738 | G8: 17310 | H8: 17218 | I8: 16427 | J8: 15262 | K8: 12654 | L8: 10307
B9: Other operating charges | C9: 313 | D9: 819 | E9: 732 | F9: 447 | G9: 895 | H9: 1183 | I9: 1657 | J9: 1510 | K9: 1902 | L9: 1079
B10: Operating Income | C10: 8231 | D10: 8413 | E10: 10173 | F10: 10779 | G10: 10228 | H10: 9708 | I10: 8728 | J10: 8626 | K10: 7599 | L10: 8700
B11: Interest income | C11: 249 | D11: 317 | E11: 483 | F11: 471 | G11: 534 | H11: 594 | I11: 613 | J11: 642 | K11: 677 | L11: 682
B12: Interest expense | C12: 355 | D12: 733 | E12: 417 | F12: 397 | G12: 463 | H12: 483 | I12: 856 | J12: 733 | K12: 841 | L12: 919
B13: Equity income (loss) - net | C13: 781 | D13: 1025 | E13: 690 | F13: 819 | G13: 602 | H13: 769 | I13: 489 | J13: 835 | K13: 1071 | L13: 1008
B14: Other income (loss) - net | C14: 40 | D14: 5185 | E14: 529 | F14: 137 | G14: 576 | H14: -1263 | I14: 631 | J14: -1234 | K14: -1764 | L14: -1121
B15: Income before income taxes | C15: 8946 | D15: 14207 | E15: 11458 | F15: 11809 | G15: 11477 | H15: 9325 | I15: 9605 | J15: 8136 | K15: 6742 | L15: 8350
B16: Income taxes | C16: 2040 | D16: 2370 | E16: 2812 | F16: 2723 | G16: 2851 | H16: 2201 | I16: 2239 | J16: 1586 | K16: 5560 | L16: 1623
... B18: Less: Net income attributable to noncontrolling interests | C18: 82 | D18: 50 | E18: 62 | F18: 67 | G18: 42 | H18: 26 | I18: 15 | J18: 23 | K18: 35 | L18: 42
B19: Net income from continuing operations | I19: 7366 | J19: 6550 | K19: 1182 | L19: 6727
B20: Income (Loss) from Discontinued Operations, Net of Tax, Including Portion Attributable to Noncontrolling Interest | I20: 0 | J20: 0 | K20: 101 | L20: -251
B21: NET INCOME ATTRIBUTABLE TO SHAREOWNERS OF THE COCA-COLA COMPANY | C21: 6824 | D21: 11787 | E21: 8584 | F21: 9019 | G21: 8584 | H21: 7098 | I21: 7351 | J21: 6527 | K21: 1248 | L21: 6434
A23: Balance Sheet
B24: in million USD | C24: FY '09 | D24: FY '10 | E24: FY '11 | F24: FY '12 | G24: FY '13 | H24: FY '14 | I24: FY '15 | J24: FY '16 | K24: FY '17 | L24: FY '18
B25: Assets
B26: Cash and cash equivalents | C26: 7021 | D26: 8517 | E26: 12803 | F26: 8442 | G26: 10414 | H26: 8958 | I26: 7309 | J26: 8555 | K26: 6006 | L26: 8926
B27: Short-term investments | C27: 2130 | D27: 2682 | E27: 1088 | F27: 5017 | G27: 6707 | H27: 9052 | I27: 8322 | J27: 9595 | K27: 9352 | L27: 2025
B28: Total cash, cash equivalents and short-term investments | C28: 9151 | D28: 11199 | E28: 13891 | F28: 13459 | G28: 17121 | H28: 18010 | I28: 15631 | J28: 18150 | K28: 15358 | L28: 10951
B29: Marketable securities | C29: 62 | D29: 138 | E29: 144 | F29: 3092 | G29: 3147 | H29: 3665 | I29: 4269 | J29: 4051 | K29: 5317 | L29: 5013
B30: Trade accounts receivable, less allowances | C30: 3758 | D30: 4430 | E30: 4920 | F30: 4759 | G30: 4873 | H30: 4466 | I30: 3941 | J30: 3856 | K30: 3667 | L30: 3396
B31: Inventories | C31: 2354 | D31: 2650 | E31: 3092 | F31: 3264 | G31: 3277 | H31: 3100 | I31: 2902 | J31: 2675 | K31: 2655 | L31: 2766
B32: Prepaid expenses and other assets | C32: 2226 | D32: 3162 | E32: 3450 | F32: 2781 | G32: 2886 | H32: 3066 | I32: 2752 | J32: 2481 | K32: 2000 | L32: 1962
B33: Assets held for sale | E33: 0 | F33: 2973 | G33: 0 | H33: 679 | I33: 3900 | J33: 0 | K33: 7329 | L33: 6546
B34: Assets held for sale | J34: 2797 | K34: 219 | L34: 0
B35: Total current assets | C35: 17551 | D35: 21579 | E35: 25497 | F35: 30328 | G35: 31304 | H35: 32986 | I35: 33395 | J35: 34010 | K35: 36545 | L35: 30634
B36: Equity method investments | C36: 6217 | D36: 6954 | E36: 7233 | F36: 9216 | G36: 10393 | H36: 9947 | I36: 12318 | J36: 16260 | K36: 20856 | L36: 19407
B37: Other investments | C37: 538 | D37: 631 | E37: 1141 | F37: 1232 | G37: 1119 | H37: 3678 | I37: 3470 | J37: 989 | K37: 1096 | L37: 867
B38: Other assets | C38: 1976 | D38: 2121 | E38: 3495 | F38: 3585 | G38: 4661 | H38: 4407 | I38: 4110 | J38: 4248 | K38: 4230 | L38: 4139
B39: Property, plant and equipment - net | C39: 9561 | D39: 14727 | E39: 14939 | F39: 14476 | G39: 14967 | H39: 14633 | I39: 12571 | J39: 10635 | K39: 8203 | L39: 8232
B40: Deferred income tax assets | K40: 330 | L40: 2667
B41: TRADEMARKS WITH INDEFINITE LIVES | C41: 6183 | D41: 6356 | E41: 6430 | F41: 6527 | G41: 6744 | H41: 6533 | I41: 5989 | J41: 6097 | K41: 6729 | L41: 6682
B42: BOTTLERS' FRANCHISE RIGHTS WITH INDEFINITE LIVES | C42: 1953 | D42: 7511 | E42: 7770 | F42: 7405 | G42: 7415 | H42: 6689 | I42: 6000 | J42: 3676 | K42: 138 | L42: 51
B43: Goodwill | C43: 4224 | D43: 11665 | E43: 12219 | F43: 12255 | G43: 12312 | H43: 12100 | I43: 11289 | J43: 10629 | K43: 9401 | L43: 10263
...
